Workbook
Name _Hlk22631867: 'CDS Definitions'!$A$103

Sheet CDS-A
A1: Question Number | B1: Question | C1: Answer | D1: Section | E1: Sub-Section | F1: Category | G1: Student Group | H1: Cohort | I1: Residency | J1: Unit load | K1: Gender | L1: Value type
A6: A01 | B6: Name: | C6: Sara Lazenby | D6: General Information | E6: Respondent Information | F6: All | G6: All | H6: All | I6: All | J6: All | K6: All | L6: Text
A7: A02 | B7: Title: | C7: Distinguished Institutional Policy Analyst | D7: General Information | E7: Respondent Information | F7: All | G7: All | H7: All | I7: All | J7: All | K7: All | L7: Text
A8: A03 | B8: Office: | C8: Office of Data, Academic Planning & Institutional Research | D8: General Information | E8: Respondent Information | F8: All | G8: All | H8: All | I8: All | J8: All | K8: All | L8: Text
A9: A04 | B9: Mailing Address: | C9: 170 Bascom Hall, 500 Lincoln Drive | D9: General Information | E9: Respondent Information | F9: All | G9: All | H9: All | I9: All | J9: All | K9: All | L9: Text
A10: A05 | B10: City/State/Zip/Country: | C10: Madison, WI, 53706 | D10: General Information | E10: Respondent Information | F10: All | G10: All | H10: All | I10: All | J10: All | K10: All | L10: Text
A11: A06 | B11: Phone: | C11: 608-263-5945 | D11: General Information | E11: Respondent Information | F11: All | G11: All | H11: All | I11: All | J11: All | K11: All | L11: Text
A12: A07 | B12: Fax: | C12: n/a | D12: General Information | E12: Respondent Information | F12: All | G12: All | H12: All | I12: All | J12: All | K12: All | L12: Text
A13: A08 | B13: E-mail Address: | C13: sara.lazenby@wisc.edu | D13: General Information | E13: Respondent Information | F13: All | G13: All | H13: All | I13: All | J13: All | K13: All | L13: Email Address
A16: A09 | B16: Are your responses to the CDS posted for reference on your institution's Web site? | C16: Y | D16: General Information | E16: Respondent Information | F16: All | G16: All | H16: All | I16: All | J16: All | K16: All | L16: YN
A18: A010 | B18: If yes, please provide the URL of the corresponding Web page: | C18: https://data.wisc.edu/common-data-set-and-rankings/ | D18: General Information | E18: Respondent Information | F18: All | G18: All | H18: All | I18: All | J18: All | K18: All | L18: URL
A20: A0A | B20: We invite you to indicate if there are items on the CDS for which you cannot use the requested analytic convention, cannot provide data for the cohort requested, whose methodology is unclear, or about which you have questions or comments in general. This information will not be published but will help the publishers further refine CDS items. | D20: General Information | E20: Respondent Information | F20: All | G20: All | H20: All | I20: All | J20: All | K20: All | L20: Text
A24: A101 | B24: Name of College/University: | C24: University of Wisconsin--Madison | D24: General Information | E24: Address Information | F24: All | G24: All | H24: All | I24: All | J24: All | K24: All | L24: Text
A25: A102 | B25: Mailing Address: | C25: 500 Lincoln Drive | D25: General Information | E25: Address Information | F25: All | G25: All | H25: All | I25: All | J25: All | K25: All | L25: Text
A26: A103 | B26: City/State/Zip/Country: | C26: Madison, WI 53706 | D26: General Information | E26: Address Information | F26: All | G26: All | H26: All | I26: All | J26: All | K26: All | L26: Text
A27: A104 | B27: Street Address (if different): | D27: General Information | E27: Address Information | F27: All | G27: All | H27: All | I27: All | J27: All | K27: All | L27: Text
A28: A105 | B28: City/State/Zip/Country: | D28: General Information | E28: Address Information | F28: All | G28: All | H28: All | I28: All | J28: All | K28: All | L28: Text
A29: A106 | B29: Main Phone Number: | C29: 608-263-2400 | D29: General Information | E29: Address Information | F29: All | G29: All | H29: All | I29: All | J29: All | K29: All | L29: Text
A30: A107 | B30: WWW Home Page Address: | C30: https://www.wisc.edu | D30: General Information | E30: Address Information | F30: All | G30: All | H30: All | I30: All | J30: All | K30: All | L30: Text
A31: A108 | B31: Admissions Phone Number: | C31: 608-262-3691 | D31: General Information | E31: Address Information | F31: All | G31: All | H31: All | I31: All | J31: All | K31: All | L31: Text
A32: A109 | B32: Admissions Toll-Free Phone Number: | D32: General Information | E32: Address Information | F32: All | G32: All | H32: All | I32: All | J32: All | K32: All | L32: Text
A33: A110 | B33: Admissions Office Mailing Address: | C33: 702 West Johnson Street, Suite 1101 | D33: General Information | E33: Address Information | F33: All | G33: All | H33: All | I33: All | J33: All | K33: All | L33: Text
A34: A111 | B34: City/State/Zip/Country: | C34: Madison, WI 53715 | D34: General Information | E34: Address Information | F34: All | G34: All | H34: All | I34: All | J34: All | K34: All | L34: Text
A35: A112 | B35: Admissions E-mail Address: | C35: onwisconsin@admissions.wisc.edu | D35: General Information | E35: Address Information | F35: All | G35: All | H35: All | I35: All | J35: All | K35: All | L35: Email Address
A37: A113 | B37: If there is a separate URL for your school’s online application, please specify: | C37: https://admissions.wisc.edu/apply-as-a-freshman/ | D37: General Information | E37: Address Information | F37: All | G37: All | H37: All | I37: All | J37: All | K37: All | L37: URL
A39: A114 | B39: If you have a mailing address other than the above to which applications should be sent, please provide: | D39: General Information | E39: Address Information | F39: All | G39: All | H39: All | I39: All | J39: All | K39: All | L39: Text
A43: A201 | B43: Public | C43: x | D43: General Information | E43: Institutional Control | F43: All | G43: All | H43: All | I43: All | J43: All | K43: All | L43: x
A44: A202 | B44: Private (nonprofit) | D44: General Information | E44: Institutional Control | F44: All | G44: All | H44: All | I44: All | J44: All | K44: All | L44: x
A45: A203 | B45: Proprietary | D45: General Information | E45: Institutional Control | F45: All | G45: All | H45: All | I45: All | J45: All | K45: All | L45: x
A48: A301 | B48: Coeducational college | C48: x | D48: General Information | E48: Classification | F48: All | G48: All | H48: All | I48: All | J48: All | K48: All | L48: x
A49: A302 | B49: Men's college | D49: General Information | E49: Classification | F49: All | G49: All | H49: All | I49: All | J49: All | K49: All | L49: x
A50: A303 | B50: Women's college | D50: General Information | E50: Classification | F50: All | G50: All | H50: All | I50: All | J50: All | K50: All | L50: x
A53: A401 | B53: Semester | C53: x | D53: General Information | E53: Academic Year | F53: All | G53: All | H53: All | I53: All | J53: All | K53: All | L53: x
A54: A402 | B54: Quarter | D54: General Information | E54: Academic Year | F54: All | G54: All | H54: All | I54: All | J54: All | K54: All | L54: x
A55: A403 | B55: Trimester | D55: General Information | E55: Academic Year | F55: All | G55: All | H55: All | I55: All | J55: All | K55: All | L55: x
A56: A404 | B56: 4-1-4 | D56: General Information | E56: Academic Year | F56: All | G56: All | H56: All | I56: All | J56: All | K56: All | L56: x
A57: A405 | B57: Continuous | D57: General Information | E57: Academic Year | F57: All | G57: All | H57: All | I57: All | J57: All | K57: All | L57: x
A59: A406 | B59: Differs by program (describe): | D59: General Information | E59: Academic Year | F59: All | G59: All | H59: All | I59: All | J59: All | K59: All | L59: Text
A60: A407 | B60: Other (describe) | D60: General Information | E60: Academic Year | F60: All | G60: All | H60: All | I60: All | J60: All | K60: All | L60: Text
A63: A501 | B63: Certificate | C63: x | D63: General Information | E63: Degrees Offered | F63: All | G63: All | H63: All | I63: All | J63: All | K63: All | L63: x
...

Sheet CDS-B
A1: Question Number | B1: Question | C1: Answer | D1: Section | E1: Sub-Section | F1: Category | G1: Student Group | H1: Cohort | I1: Residency | J1: Unit load | K1: Gender | L1: Value type
A16: B101 | B16: Degree-seeking, first-time first-year students: men | C16: 3768 | D16: Enrollment And Persistence | E16: Institutional Enrollment | F16: Degree-seeking | G16: Undergraduates | H16: First-time, first-year | I16: All | J16: FT | K16: Men | L16: Number
A17: B102 | B17: Degree-seeking, first-time first-year students: women | C17: 4722 | D17: Enrollment And Persistence | E17: Institutional Enrollment | F17: Degree-seeking | G17: Undergraduates | H17: First-time, first-year | I17: All | J17: FT | K17: Women | L17: Number
A18: B103 | B18: Degree-seeking, first-time first-year students: another gender | C18: 1 | D18: Enrollment And Persistence | E18: Institutional Enrollment | F18: Degree-seeking | G18: Undergraduates | H18: First-time, first-year | I18: All | J18: FT | K18: Another Gender | L18: Number
A19: B104 | B19: Degree-seeking, first-time first-year students: unknown | C19: 0 | D19: Enrollment And Persistence | E19: Institutional Enrollment | F19: Degree-seeking | G19: Undergraduates | H19: First-time, first-year | I19: All | J19: FT | K19: Unknown | L19: Number
A21: B105 | B21: Other first-year, degree-seeking: men | C21: 0 | D21: Enrollment And Persistence | E21: Institutional Enrollment | F21: Degree-seeking | G21: Undergraduates | H21: Other first-year | I21: All | J21: FT | K21: Men | L21: Number
A22: B106 | B22: Other first-year, degree-seeking: women | C22: 0 | D22: Enrollment And Persistence | E22: Institutional Enrollment | F22: Degree-seeking | G22: Undergraduates | H22: Other first-year | I22: All | J22: FT | K22: Women | L22: Number
A23: B107 | B23: Other first-year, degree-seeking: another gender | C23: 0 | D23: Enrollment And Persistence | E23: Institutional Enrollment | F23: Degree-seeking | G23: Undergraduates | H23: Other first-year | I23: All | J23: FT | K23: Another Gender | L23: Number
A24: B108 | B24: Other first-year, degree-seeking: unknown | C24: 0 | D24: Enrollment And Persistence | E24: Institutional Enrollment | F24: Degree-seeking | G24: Undergraduates | H24: Other first-year | I24: All | J24: FT | K24: Unknown | L24: Number
A26: B109 | B26: All other degree-seeking: men | C26: 12535 | D26: Enrollment And Persistence | E26: Institutional Enrollment | F26: Degree-seeking | G26: Undergraduates | H26: All other | I26: All | J26: FT | K26: Men | L26: Number
A27: B110 | B27: All other degree-seeking: women | C27: 14167 | D27: Enrollment And Persistence | E27: Institutional Enrollment | F27: Degree-seeking | G27: Undergraduates | H27: All other | I27: All | J27: FT | K27: Women | L27: Number
A28: B111 | B28: All other degree-seeking: another gender | C28: 3 | D28: Enrollment And Persistence | E28: Institutional Enrollment | F28: Degree-seeking | G28: Undergraduates | H28: All other | I28: All | J28: FT | K28: Another Gender | L28: Number
A29: B112 | B29: All other degree-seeking: unknown | D29: Enrollment And Persistence | E29: Institutional Enrollment | F29: Degree-seeking | G29: Undergraduates | H29: All other | I29: All | J29: FT | K29: Unknown | L29: Number
A31: B113 | B31: Total degree-seeking: men | C31: =SUM(C26,C21,C16) | D31: Enrollment And Persistence | E31: Institutional Enrollment | F31: Degree-seeking | G31: Undergraduates | H31: Total | I31: All | J31: FT | K31: Men | L31: Number
A32: B114 | B32: Total degree-seeking: women | C32: =SUM(C27,C22,C17) | D32: Enrollment And Persistence | E32: Institutional Enrollment | F32: Degree-seeking | G32: Undergraduates | H32: Total | I32: All | J32: FT | K32: Women | L32: Number
A33: B115 | B33: Total degree-seeking: another gender | C33: =SUM(C28,C23,C18) | D33: Enrollment And Persistence | E33: Institutional Enrollment | F33: Degree-seeking | G33: Undergraduates | H33: Total | I33: All | J33: FT | K33: Another Gender | L33: Number
A34: B116 | B34: Total degree-seeking: unknown | C34: =SUM(C29,C24,C19) | D34: Enrollment And Persistence | E34: Institutional Enrollment | F34: Degree-seeking | G34: Undergraduates | H34: Total | I34: All | J34: FT | K34: Unknown | L34: Number
A36: B117 | B36: All other undergraduates enrolled in credit courses: men | C36: 175 | D36: Enrollment And Persistence | E36: Institutional Enrollment | F36: Enrolled in Credit Courses | G36: Undergraduates | H36: All other | I36: All | J36: FT | K36: Men | L36: Number
A37: B118 | B37: All other undergraduates enrolled in credit courses: women | C37: 137 | D37: Enrollment And Persistence | E37: Institutional Enrollment | F37: Enrolled in Credit Courses | G37: Undergraduates | H37: All other | I37: All | J37: FT | K37: Women | L37: Number
A38: B119 | B38: All other undergraduates enrolled in credit courses: another gender | C38: 0 | D38: Enrollment And Persistence | E38: Institutional Enrollment | F38: Enrolled in Credit Courses | G38: Undergraduates | H38: All other | I38: All | J38: FT | K38: Another Gender | L38: Number
A39: B120 | B39: All other undergraduates enrolled in credit courses: unknown | C39: 0 | D39: Enrollment And Persistence | E39: Institutional Enrollment | F39: Enrolled in Credit Courses | G39: Undergraduates | H39: All other | I39: All | J39: FT | K39: Unknown | L39: Number
A41: B121 | B41: Total undergraduate Full-Time Students: men | C41: =SUM(C31,C36) | D41: Enrollment And Persistence | E41: Institutional Enrollment | F41: All | G41: Undergraduates | H41: Total | I41: All | J41: FT | K41: Men | L41: Number
A42: B122 | B42: Total undergraduate Full-Time Students: women | C42: =SUM(C32,C37) | D42: Enrollment And Persistence | E42: Institutional Enrollment | F42: All | G42: Undergraduates | H42: Total | I42: All | J42: FT | K42: Women | L42: Number
A43: B123 | B43: Total undergraduate Full-Time Students: another gender | C43: =SUM(C33,C38) | D43: Enrollment And Persistence | E43: Institutional Enrollment | F43: All | G43: Undergraduates | H43: Total | I43: All | J43: FT | K43: Another Gender | L43: Number
A44: B124 | B44: Total undergraduate Full-Time Students: unknown | C44: =SUM(C34,C39) | D44: Enrollment And Persistence | E44: Institutional Enrollment | F44: All | G44: Undergraduates | H44: Total | I44: All | J44: FT | K44: Unknown | L44: Number
A47: B125 | B47: Degree-seeking, first-time first-year students: men | C47: 11 | D47: Enrollment And Persistence | E47: Institutional Enrollment | F47: Degree-seeking | G47: Undergraduates | H47: First-time, first-year | I47: All | J47: PT | K47: Men | L47: Number
A48: B126 | B48: Degree-seeking, first-time first-year students: women | C48: 12 | D48: Enrollment And Persistence | E48: Institutional Enrollment | F48: Degree-seeking | G48: Undergraduates | H48: First-time, first-year | I48: All | J48: PT | K48: Women | L48: Number
A49: B127 | B49: Degree-seeking, first-time first-year students: another gender | C49: 0 | D49: Enrollment And Persistence | E49: Institutional Enrollment | F49: Degree-seeking | G49: Undergraduates | H49: First-time, first-year | I49: All | J49: PT | K49: Another Gender | L49: Number
A50: B128 | B50: Degree-seeking, first-time first-year students: unknown | C50: 0 | D50: Enrollment And Persistence | E50: Institutional Enrollment | F50: Degree-seeking | G50: Undergraduates | H50: First-time, first-year | I50: All | J50: PT | K50: Unknown | L50: Number
A52: B129 | B52: Other first-year, degree-seeking: men | C52: 0 | D52: Enrollment And Persistence | E52: Institutional Enrollment | F52: Degree-seeking | G52: Undergraduates | H52: Other first-year | I52: All | J52: PT | K52: Men | L52: Number
A53: B130 | B53: Other first-year, degree-seeking: women | C53: 0 | D53: Enrollment And Persistence | E53: Institutional Enrollment | F53: Degree-seeking | G53: Undergraduates | H53: Other first-year | I53: All | J53: PT | K53: Women | L53: Number
A54: B131 | B54: Other first-year, degree-seeking: another gender | C54: 0 | D54: Enrollment And Persistence | E54: Institutional Enrollment | F54: Degree-seeking | G54: Undergraduates | H54: Other first-year | I54: All | J54: PT | K54: Another Gender | L54: Number
A55: B132 | B55: Other first-year, degree-seeking: unknown | C55: 0 | D55: Enrollment And Persistence | E55: Institutional Enrollment | F55: Degree-seeking | G55: Undergraduates | H55: Other first-year | I55: All | J55: PT | K55: Unknown | L55: Number
A57: B133 | B57: All other degree-seeking: men | C57: 886 | D57: Enrollment And Persistence | E57: Institutional Enrollment | F57: Degree-seeking | G57: Undergraduates | H57: All other | I57: All | J57: PT | K57: Men | L57: Number
A58: B134 | B58: All other degree-seeking: women | C58: 797 | D58: Enrollment And Persistence | E58: Institutional Enrollment | F58: Degree-seeking | G58: Undergraduates | H58: All other | I58: All | J58: PT | K58: Women | L58: Number
A59: B135 | B59: All other degree-seeking: another gender | C59: 0 | D59: Enrollment And Persistence | E59: Institutional Enrollment | F59: Degree-seeking | G59: Undergraduates | H59: All other | I59: All | J59: PT | K59: Another Gender | L59: Number
A60: B136 | B60: All other degree-seeking: unknown | C60: 0 | D60: Enrollment And Persistence | E60: Institutional Enrollment | F60: Degree-seeking | G60: Undergraduates | H60: All other | I60: All | J60: PT | K60: Unknown | L60: Number
A62: B137 | B62: Total degree-seeking: men | C62: =SUM(C57,C52,C47) | D62: Enrollment And Persistence | E62: Institutional Enrollment | F62: Degree-seeking | G62: Undergraduates | H62: Total | I62: All | J62: PT | K62: Men | L62: Number
A63: B138 | B63: Total degree-seeking: women | C63: =SUM(C58,C53,C48) | D63: Enrollment And Persistence | E63: Institutional Enrollment | F63: Degree-seeking | G63: Undergraduates | H63: Total | I63: All | J63: PT | K63: Women | L63: Number
A64: B139 | B64: Total degree-seeking: another gender | C64: =SUM(C59,C54,C49) | D64: Enrollment And Persistence | E64: Institutional Enrollment | F64: Degree-seeking | G64: Undergraduates | H64: Total | I64: All | J64: PT | K64: Another Gender | L64: Number
...

Sheet CDS-C
A1: Question Number | B1: Question | C1: Answer | D1: Section | E1: Sub-Section | F1: Category | G1: Student Group | H1: Cohort | I1: Residency | J1: Unit load | K1: Gender | L1: Value type
A27: C101 | B27: Total first-time, first-year men who applied | C27: 32863 | D27: First-Time, First-Year Admission | E27: Applications | F27: Applied | G27: Undergraduates | H27: First-time, first-year | I27: All | J27: All | K27: Men | L27: Number
A28: C102 | B28: Total first-time, first-year women who applied | C28: 33050 | D28: First-Time, First-Year Admission | E28: Applications | F28: Applied | G28: Undergraduates | H28: First-time, first-year | I28: All | J28: All | K28: Women | L28: Number
A29: C103 | B29: Total first-time, first-year another gender who applied | C29: 20 | D29: First-Time, First-Year Admission | E29: Applications | F29: Applied | G29: Undergraduates | H29: First-time, first-year | I29: All | J29: All | K29: Another Gender | L29: Number
A30: C104 | B30: Total first-time, first-year unknown gender who applied | C30: 0 | D30: First-Time, First-Year Admission | E30: Applications | F30: Applied | G30: Undergraduates | H30: First-time, first-year | I30: All | J30: All | K30: Unknown | L30: Number
A33: C105 | B33: Total first-time, first-year men who were admitted | C33: 13835 | D33: First-Time, First-Year Admission | E33: Applications | F33: Admitted | G33: Undergraduates | H33: First-time, first-year | I33: All | J33: All | K33: Men | L33: Number
A34: C106 | B34: Total first-time, first-year women who were admitted | C34: 15940 | D34: First-Time, First-Year Admission | E34: Applications | F34: Admitted | G34: Undergraduates | H34: First-time, first-year | I34: All | J34: All | K34: Women | L34: Number
A35: C107 | B35: Total first-time, first-year another gender who were admitted | C35: 9 | D35: First-Time, First-Year Admission | E35: Applications | F35: Admitted | G35: Undergraduates | H35: First-time, first-year | I35: All | J35: All | K35: Another Gender | L35: Number
A36: C108 | B36: Total first-time, first-year unknown gender who were admitted | C36: 0 | D36: First-Time, First-Year Admission | E36: Applications | F36: Admitted | G36: Undergraduates | H36: First-time, first-year | I36: All | J36: All | K36: Unknown | L36: Number
A39: C109 | B39: Total full-time, first-time, first-year men who enrolled | C39: 3768 | D39: First-Time, First-Year Admission | E39: Applications | F39: Enrolled | G39: Undergraduates | H39: First-time, first-year | I39: All | J39: All | K39: Men | L39: Number
A40: C110 | B40: Total part-time, first-time, first-year men who enrolled | C40: 11 | D40: First-Time, First-Year Admission | E40: Applications | F40: Enrolled | G40: Undergraduates | H40: First-time, first-year | I40: All | J40: PT | K40: Men | L40: Number
A41: C111 | B41: Total full-time, first-time, first-year women who enrolled | C41: 4722 | D41: First-Time, First-Year Admission | E41: Applications | F41: Enrolled | G41: Undergraduates | H41: First-time, first-year | I41: All | J41: FT | K41: Women | L41: Number
A42: C112 | B42: Total part-time, first-time, first-year women who enrolled | C42: 12 | D42: First-Time, First-Year Admission | E42: Applications | F42: Enrolled | G42: Undergraduates | H42: First-time, first-year | I42: All | J42: PT | K42: Women | L42: Number
... A46: C116 | B46: Total part-time, first-time, first-year unknown gender who enrolled | C46: 0 | D46: First-Time, First-Year Admission | E46: Applications | F46: Enrolled | G46: Undergraduates | H46: First-time, first-year | I46: All | J46: PT | K46: Unknown | L46: Number
A49: C117 | B49: Total first-time, first-year students who applied | C49: =SUM(C27:C30) | D49: First-Time, First-Year Admission | E49: Applications | F49: Applied | G49: Undergraduates | H49: First-time, first-year | I49: All | J49: All | K49: All | L49: Number
A50: C118 | B50: Total first-time, first-year students who were admitted | C50: =SUM(C33:C36) | D50: First-Time, First-Year Admission | E50: Applications | F50: Admitted | G50: Undergraduates | H50: First-time, first-year | I50: All | J50: All | K50: All | L50: Number
A51: C119 | B51: Total first-time, first-year students who enrolled | C51: =SUM(C39:C46) | D51: First-Time, First-Year Admission | E51: Applications | F51: Enrolled | G51: Undergraduates | H51: First-time, first-year | I51: All | J51: All | K51: All | L51: Number
A60: C120 | B60: Total first-time, first-year who applied | D60: First-Time, First-Year Admission | E60: Applications | F60: Applied | G60: Undergraduates | H60: First-time, first-year | I60: In-State | J60: All | K60: All | L60: Number
A61: C121 | B61: Total first-time, first-year who were admitted | D61: First-Time, First-Year Admission | E61: Applications | F61: Admitted | G61: Undergraduates | H61: First-time, first-year | I61: In-State | J61: All | K61: All | L61: Number
A62: C122 | B62: Total first-time, first-year who enrolled | D62: First-Time, First-Year Admission | E62: Applications | F62: Enrolled | G62: Undergraduates | H62: First-time, first-year | I62: In-State | J62: All | K62: All | L62: Number
A65: C123 | B65: Total first-time, first-year who applied | D65: First-Time, First-Year Admission | E65: Applications | F65: Applied | G65: Undergraduates | H65: First-time, first-year | I65: Out-of-State | J65: All | K65: All | L65: Number
A66: C124 | B66: Total first-time, first-year who were admitted | D66: First-Time, First-Year Admission | E66: Applications | F66: Admitted | G66: Undergraduates | H66: First-time, first-year | I66: Out-of-State | J66: All | K66: All | L66: Number
A67: C125 | B67: Total first-time, first-year who enrolled | D67: First-Time, First-Year Admission | E67: Applications | F67: Enrolled | G67: Undergraduates | H67: First-time, first-year | I67: Out-of-State | J67: All | K67: All | L67: Number
A70: C126 | B70: Total first-time, first-year who applied | D70: First-Time, First-Year Admission | E70: Applications | F70: Applied | G70: Undergraduates | H70: First-time, first-year | I70: Nonresidents | J70: All | K70: All | L70: Number
A71: C127 | B71: Total first-time, first-year who were admitted | D71: First-Time, First-Year Admission | E71: Applications | F71: Admitted | G71: Undergraduates | H71: First-time, first-year | I71: Nonresidents | J71: All | K71: All | L71: Number
A72: C128 | B72: Total first-time, first-year who enrolled | D72: First-Time, First-Year Admission | E72: Applications | F72: Enrolled | G72: Undergraduates | H72: First-time, first-year | I72: Nonresidents | J72: All | K72: All | L72: Number
A75: C129 | B75: Total first-time, first-year who applied | D75: First-Time, First-Year Admission | E75: Applications | F75: Applied | G75: Undergraduates | H75: First-time, first-year | I75: Unknown | J75: All | K75: All | L75: Number
A76: C130 | B76: Total first-time, first-year who were admitted | D76: First-Time, First-Year Admission | E76: Applications | F76: Admitted | G76: Undergraduates | H76: First-time, first-year | I76: Unknown | J76: All | K76: All | L76: Number
A77: C131 | B77: Total first-time, first-year who enrolled | D77: First-Time, First-Year Admission | E77: Applications | F77: Enrolled | G77: Undergraduates | H77: First-time, first-year | I77: Unknown | J77: All | K77: All | L77: Number
A85: C201 | B85: Do you have a policy of placing students on a waiting list? | C85: Y | D85: First-Time, First-Year Admission | E85: Wait List | F85: Policy | G85: Undergraduates | H85: First-time, first-year | I85: All | J85: All | K85: All | L85: YN
A91: C202 | B91: Number of qualified applicants offered a place on waiting list: | C91: 12584 | D91: First-Time, First-Year Admission | E91: Wait List | F91: Applied | G91: Undergraduates | H91: First-time, first-year | I91: All | J91: All | K91: All | L91: Number
A92: C203 | B92: Number accepting a place on the waiting list: | C92: 7644 | D92: First-Time, First-Year Admission | E92: Wait List | F92: Accepting Offer | G92: Undergraduates | H92: First-time, first-year | I92: All | J92: All | K92: All | L92: Number
A93: C204 | B93: Number of wait-listed students admitted: | C93: 493 | D93: First-Time, First-Year Admission | E93: Wait List | F93: Admitted | G93: Undergraduates | H93: First-time, first-year | I93: All | J93: All | K93: All | L93: Number
A96: C205 | B96: Is your waiting list ranked? | C96: N | D96: First-Time, First-Year Admission | E96: Wait List | F96: Policy | G96: Undergraduates | H96: First-time, first-year | I96: All | J96: All | K96: All | L96: YN
A97: C206 | B97: If yes, do you release that information to students? | D97: First-Time, First-Year Admission | E97: Wait List | F97: Policy | G97: Undergraduates | H97: First-time, first-year | I97: All | J97: All | K97: All | L97: YN
A98: C207 | B98: Do you release that information to school counselors? | D98: First-Time, First-Year Admission | E98: Wait List | F98: Policy | G98: Undergraduates | H98: First-time, first-year | I98: All | J98: All | K98: All | L98: YN
A110: C301 | B110: High school diploma is required and GED is accepted | C110: X | D110: First-Time, First-Year Admission | E110: Admissions Requirements | F110: High School completion | G110: Undergraduates | H110: First-time, first-year | I110: All | J110: All | K110: All | L110: x
A111: C302 | B111: High school diploma is required and GED is not accepted | D111: First-Time, First-Year Admission | E111: Admissions Requirements | F111: High School completion | G111: Undergraduates | H111: First-time, first-year | I111: All | J111: All | K111: All | L111: x
A112: C303 | B112: High school diploma or equivalent is not required | D112: First-Time, First-Year Admission | E112: Admissions Requirements | F112: High School completion | G112: Undergraduates | H112: First-time, first-year | I112: All | J112: All | K112: All | L112: x
A118: C401 | B118: Require | C118: x | D118: First-Time, First-Year Admission | E118: Admissions Requirements | F118: College-preparatory Program | G118: Undergraduates | H118: First-time, first-year | I118: All | J118: All | K118: All | L118: x
...

Sheet CDS-D
A1: Question Number | B1: Question | C1: Answer | D1: Section | E1: Sub-Section | F1: Category | G1: Student Group | H1: Cohort | I1: Residency | J1: Unit load | K1: Gender | L1: Value type
A9: D101 | B9: Does your institution enroll transfer students? (If no, please skip to Section E) | C9: Y | D9: Transfer Admission | E9: Fall Applicants | F9: All | G9: Undergraduates | H9: Transfer | I9: All | J9: All | K9: All | L9: YN
A10: D102 | B10: If yes, may transfer students earn advanced standing credit by transferring credits earned from course work completed at other colleges/universities? | C10: Y | D10: Transfer Admission | E10: Fall Applicants | F10: All | G10: Undergraduates | H10: Transfer | I10: All | J10: All | K10: All | L10: YN
A19: D201 | B19: Men | C19: 2496 | D19: Transfer Admission | E19: Fall Applicants | F19: Applied | G19: Undergraduates | H19: Transfer | I19: All | J19: All | K19: Men | L19: Number
A20: D202 | B20: Women | C20: 2020 | D20: Transfer Admission | E20: Fall Applicants | F20: Applied | G20: Undergraduates | H20: Transfer | I20: All | J20: All | K20: Women | L20: Number
A21: D203 | B21: Another Gender | C21: 0 | D21: Transfer Admission | E21: Fall Applicants | F21: Applied | G21: Undergraduates | H21: Transfer | I21: All | J21: All | K21: Another Gender | L21: Number
A22: D204 | B22: Unknown | C22: 0 | D22: Transfer Admission | E22: Fall Applicants | F22: Applied | G22: Undergraduates | H22: Transfer | I22: All | J22: All | K22: Unknown | L22: Number
A23: D205 | B23: Total | C23: =SUM(C19:C22) | D23: Transfer Admission | E23: Fall Applicants | F23: Applied | G23: Undergraduates | H23: Transfer | I23: All | J23: All | K23: All | L23: Number
A27: D206 | B27: Men | C27: 1386 | D27: Transfer Admission | E27: Fall Applicants | F27: Admitted | G27: Undergraduates | H27: Transfer | I27: All | J27: All | K27: Men | L27: Number
A28: D207 | B28: Women | C28: 1121 | D28: Transfer Admission | E28: Fall Applicants | F28: Admitted | G28: Undergraduates | H28: Transfer | I28: All | J28: All | K28: Women | L28: Number
A29: D208 | B29: Another Gender | C29: 0 | D29: Transfer Admission | E29: Fall Applicants | F29: Admitted | G29: Undergraduates | H29: Transfer | I29: All | J29: All | K29: Another Gender | L29: Number
A30: D209 | B30: Unknown | C30: 0 | D30: Transfer Admission | E30: Fall Applicants | F30: Admitted | G30: Undergraduates | H30: Transfer | I30: All | J30: All | K30: Unknown | L30: Number
A31: D210 | B31: Total | C31: =SUM(C27:C29) | D31: Transfer Admission | E31: Fall Applicants | F31: Admitted | G31: Undergraduates | H31: Transfer | I31: All | J31: All | K31: All | L31: Number
A34: D211 | B34: Men | C34: 746 | D34: Transfer Admission | E34: Fall Applicants | F34: Enrolled | G34: Undergraduates | H34: Transfer | I34: All | J34: All | K34: Men | L34: Number
A35: D212 | B35: Women | C35: 627 | D35: Transfer Admission | E35: Fall Applicants | F35: Enrolled | G35: Undergraduates | H35: Transfer | I35: All | J35: All | K35: Women | L35: Number
A36: D213 | B36: Another Gender | C36: 0 | D36: Transfer Admission | E36: Fall Applicants | F36: Enrolled | G36: Undergraduates | H36: Transfer | I36: All | J36: All | K36: Another Gender | L36: Number
A37: D214 | B37: Unknown | C37: 0 | D37: Transfer Admission | E37: Fall Applicants | F37: Enrolled | G37: Undergraduates | H37: Transfer | I37: All | J37: All | K37: Unknown | L37: Number
A38: D215 | B38: Total | C38: =SUM(C34:C36) | D38: Transfer Admission | E38: Fall Applicants | F38: Enrolled | G38: Undergraduates | H38: Transfer | I38: All | J38: All | K38: All | L38: Number
A44: D301 | B44: Fall | C44: x | D44: Transfer Admission | E44: Application for Admission | F44: Fall | G44: Undergraduates | H44: Transfer | I44: All | J44: All | K44: All | L44: x
A45: D302 | B45: Winter | D45: Transfer Admission | E45: Application for Admission | F45: Winter | G45: Undergraduates | H45: Transfer | I45: All | J45: All | K45: All | L45: x
A46: D303 | B46: Spring | C46: x | D46: Transfer Admission | E46: Application for Admission | F46: Spring | G46: Undergraduates | H46: Transfer | I46: All | J46: All | K46: All | L46: x
A47: D304 | B47: Summer | D47: Transfer Admission | E47: Application for Admission | F47: Summer | G47: Undergraduates | H47: Transfer | I47: All | J47: All | K47: All | L47: x
A50: D401 | B50: Must a transfer applicant have a minimum number of credits completed or else must apply as an entering first-year student? | C50: Y | D50: Transfer Admission | E50: Application for Admission | F50: Min Credits | G50: Undergraduates | H50: Transfer | I50: All | J50: All | K50: All | L50: YN
A55: D402 | B55: Number | C55: 24 | D55: Transfer Admission | E55: Transfer Credit Policies | F55: Min Credits | G55: Undergraduates | H55: Transfer | I55: All | J55: All | K55: All | L55: Number
A56: D403 | B56: Unit Type | C56: Credits | D56: Transfer Admission | E56: Transfer Credit Policies | F56: Min Credits | G56: Undergraduates | H56: Transfer | I56: All | J56: All | K56: All | L56: Unit Type
C59: Required of All
C60: Recommended of All
C61: Recommended of Some
C62: Required of Some
C63: Not Required
A66: D501 | B66: High school transcript | C66: Required of All | D66: Transfer Admission | E66: Application for Admission | F66: Requirements | G66: Undergraduates | H66: Transfer | I66: All | J66: All | K66: All | L66: Text
A67: D502 | B67: College transcript(s) | C67: Required of All | D67: Transfer Admission | E67: Application for Admission | F67: Requirements | G67: Undergraduates | H67: Transfer | I67: All | J67: All | K67: All | L67: Text
A68: D503 | B68: Essay or personal statement | C68: Required of All | D68: Transfer Admission | E68: Application for Admission | F68: Requirements | G68: Undergraduates | H68: Transfer | I68: All | J68: All | K68: All | L68: Text
A69: D504 | B69: Interview | C69: Not Required | D69: Transfer Admission | E69: Application for Admission | F69: Requirements | G69: Undergraduates | H69: Transfer | I69: All | J69: All | K69: All | L69: Text
A70: D505 | B70: Standardized test scores | C70: Not Required | D70: Transfer Admission | E70: Application for Admission | F70: Requirements | G70: Undergraduates | H70: Transfer | I70: All | J70: All | K70: All | L70: Text
A71: D506 | B71: Statement of good standing from prior institution(s) | C71: Not Required | D71: Transfer Admission | E71: Application for Admission | F71: Requirements | G71: Undergraduates | H71: Transfer | I71: All | J71: All | K71: All | L71: Text
A74: D601 | B74: If a minimum high school grade point average is required of transfer applicants, specify (on a 4.0 scale): | D74: Transfer Admission | E74: Application for Admission | F74: Requirements | G74: Undergraduates | H74: Transfer | I74: All | J74: All | K74: All | L74: Round to Nearest Hundredths
A77: D701 | B77: If a minimum college grade point average is required of transfer applicants, specify (on a 4.0 scale): | D77: Transfer Admission | E77: Application for Admission | F77: Requirements | G77: Undergraduates | H77: Transfer | I77: All | J77: All | K77: All | L77: Round to Nearest Hundredths
A80: D801 | B80: List any other application requirements specific to transfer applicants: | D80: Transfer Admission | E80: Application for Admission | F80: Requirements | G80: Undergraduates | H80: Transfer | I80: All | J80: All | K80: All | L80: Text
A88: D901 | B88: Fall | C88: 46054 | D88: Transfer Admission | E88: Application for Admission | F88: Dates | G88: Undergraduates | H88: Transfer | I88: All | J88: All | K88: All | L88: MM-DD
...

Sheet CDS-E
A1: Question Number | B1: Question | C1: Answer | D1: Section | E1: Sub-Section | F1: Category | G1: Student Group | H1: Cohort | I1: Residency | J1: Unit load | K1: Gender | L1: Value type
A10: E101 | B10: Accelerated program | C10: x | D10: Academic Offerings and Policies | E10: Special Study Options | F10: All | G10: All | H10: All | I10: All | J10: All | K10: All | L10: x
A11: E102 | B11: Comprehensive transition and postsecondary program for students with intellectual disabilities | D11: Academic Offerings and Policies | E11: Special Study Options | F11: All | G11: All | H11: All | I11: All | J11: All | K11: All | L11: x
A12: E103 | B12: Cross-registration | D12: Academic Offerings and Policies | E12: Special Study Options | F12: All | G12: All | H12: All | I12: All | J12: All | K12: All | L12: x
A13: E104 | B13: Distance learning | C13: x | D13: Academic Offerings and Policies | E13: Special Study Options | F13: All | G13: All | H13: All | I13: All | J13: All | K13: All | L13: x
A14: E105 | B14: Double major | C14: x | D14: Academic Offerings and Policies | E14: Special Study Options | F14: All | G14: All | H14: All | I14: All | J14: All | K14: All | L14: x
A15: E106 | B15: Dual enrollment | D15: Academic Offerings and Policies | E15: Special Study Options | F15: All | G15: All | H15: All | I15: All | J15: All | K15: All | L15: x
A16: E107 | B16: English as a Second Language (ESL) | D16: Academic Offerings and Policies | E16: Special Study Options | F16: All | G16: All | H16: All | I16: All | J16: All | K16: All | L16: x
A17: E108 | B17: Exchange student program (domestic) | C17: x | D17: Academic Offerings and Policies | E17: Special Study Options | F17: All | G17: All | H17: All | I17: All | J17: All | K17: All | L17: x
A18: E109 | B18: External degree program | D18: Academic Offerings and Policies | E18: Special Study Options | F18: All | G18: All | H18: All | I18: All | J18: All | K18: All | L18: x
A19: E110 | B19: Honors Program | C19: x | D19: Academic Offerings and Policies | E19: Special Study Options | F19: All | G19: All | H19: All | I19: All | J19: All | K19: All | L19: x
A20: E111 | B20: Independent study | C20: x | D20: Academic Offerings and Policies | E20: Special Study Options | F20: All | G20: All | H20: All | I20: All | J20: All | K20: All | L20: x
A21: E112 | B21: Internships | C21: x | D21: Academic Offerings and Policies | E21: Special Study Options | F21: All | G21: All | H21: All | I21: All | J21: All | K21: All | L21: x
A22: E113 | B22: Liberal arts/career combination | C22: x | D22: Academic Offerings and Policies | E22: Special Study Options | F22: All | G22: All | H22: All | I22: All | J22: All | K22: All | L22: x
A23: E114 | B23: Student-designed major | C23: x | D23: Academic Offerings and Policies | E23: Special Study Options | F23: All | G23: All | H23: All | I23: All | J23: All | K23: All | L23: x
A24: E115 | B24: Study abroad | C24: x | D24: Academic Offerings and Policies | E24: Special Study Options | F24: All | G24: All | H24: All | I24: All | J24: All | K24: All | L24: x
A25: E116 | B25: Teacher certification program | C25: x | D25: Academic Offerings and Policies | E25: Special Study Options | F25: All | G25: All | H25: All | I25: All | J25: All | K25: All | L25: x
A26: E117 | B26: Undergraduate Research | C26: x | D26: Academic Offerings and Policies | E26: Special Study Options | F26: All | G26: All | H26: All | I26: All | J26: All | K26: All | L26: x
A27: E118 | B27: Weekend college | D27: Academic Offerings and Policies | E27: Special Study Options | F27: All | G27: All | H27: All | I27: All | J27: All | K27: All | L27: x
A29: E119 | B29: Other (specify): | D29: Academic Offerings and Policies | E29: Special Study Options | F29: All | G29: All | H29: All | I29: All | J29: All | K29: All | L29: Text
A39: E301 | B39: Arts/fine arts | D39: Academic Offerings and Policies | E39: Required Course Work | F39: All | G39: All | H39: All | I39: All | J39: All | K39: All | L39: x
A40: E302 | B40: Computer literacy | D40: Academic Offerings and Policies | E40: Required Course Work | F40: All | G40: All | H40: All | I40: All | J40: All | K40: All | L40: x
A41: E303 | B41: English (including composition) | C41: x | D41: Academic Offerings and Policies | E41: Required Course Work | F41: All | G41: All | H41: All | I41: All | J41: All | K41: All | L41: x
A42: E304 | B42: Foreign languages | C42: x | D42: Academic Offerings and Policies | E42: Required Course Work | F42: All | G42: All | H42: All | I42: All | J42: All | K42: All | L42: x
A43: E305 | B43: History | C43: x | D43: Academic Offerings and Policies | E43: Required Course Work | F43: All | G43: All | H43: All | I43: All | J43: All | K43: All | L43: x
A44: E306 | B44: Physical Education | D44: Academic Offerings and Policies | E44: Required Course Work | F44: All | G44: All | H44: All | I44: All | J44: All | K44: All | L44: x
A45: E307 | B45: Humanities | C45: x | D45: Academic Offerings and Policies | E45: Required Course Work | F45: All | G45: All | H45: All | I45: All | J45: All | K45: All | L45: x
A46: E308 | B46: Intensive writing | C46: x | D46: Academic Offerings and Policies | E46: Required Course Work | F46: All | G46: All | H46: All | I46: All | J46: All | K46: All | L46: x
A47: E309 | B47: Mathematics | C47: x | D47: Academic Offerings and Policies | E47: Required Course Work | F47: All | G47: All | H47: All | I47: All | J47: All | K47: All | L47: x
A48: E310 | B48: Philosophy | D48: Academic Offerings and Policies | E48: Required Course Work | F48: All | G48: All | H48: All | I48: All | J48: All | K48: All | L48: x
A49: E311 | B49: Sciences (biological or physical) | C49: x | D49: Academic Offerings and Policies | E49: Required Course Work | F49: All | G49: All | H49: All | I49: All | J49: All | K49: All | L49: x
A50: E312 | B50: Social science | C50: x | D50: Academic Offerings and Policies | E50: Required Course Work | F50: All | G50: All | H50: All | I50: All | J50: All | K50: All | L50: x
A52: E313 | B52: Other (describe): | C52: Ethnic Studies Requirement | D52: Academic Offerings and Policies | E52: Required Course Work | F52: All | G52: All | H52: All | I52: All | J52: All | K52: All | L52: Text

Sheet CDS-F
A1: Question Number | B1: Question | C1: Answer | D1: Section | E1: Sub-Section | F1: Category | G1: Student Group | H1: Cohort | I1: Residency | J1: Unit load | K1: Gender | L1: Value type
A10: F101 | B10: Percent who are from out of state (exclude international/nonresidents from the numerator and denominator) | C10: 51 | D10: Student Life | E10: Percent Participating | F10: Degree-Seeking | G10: Undergraduates | H10: First-time, first-year | I10: All | J10: All | K10: All | L10: Nearest 1%
A11: F102 | B11: Percent of men who join fraternities | C11: 9 | D11: Student Life | E11: Percent Participating | F11: Degree-Seeking | G11: Undergraduates | H11: First-time, first-year | I11: All | J11: All | K11: All | L11: Nearest 1%
A12: F103 | B12: Percent of women who join sororities | C12: 8 | D12: Student Life | E12: Percent Participating | F12: Degree-Seeking | G12: Undergraduates | H12: First-time, first-year | I12: All | J12: All | K12: All | L12: Nearest 1%
A13: F104 | B13: Percent who live in college-owned, -operated, or -affiliated housing | C13: 93 | D13: Student Life | E13: Percent Participating | F13: Degree-Seeking | G13: Undergraduates | H13: First-time, first-year | I13: All | J13: All | K13: All | L13: Nearest 1%
A14: F105 | B14: Percent who live off campus or commute | C14: 7 | D14: Student Life | E14: Percent Participating | F14: Degree-Seeking | G14: Undergraduates | H14: First-time, first-year | I14: All | J14: All | K14: All | L14: Nearest 1%
A15: F106 | B15: Percent of students age 25 and older | C15: 0 | D15: Student Life | E15: Percent Participating | F15: Degree-Seeking | G15: Undergraduates | H15: First-time, first-year | I15: All | J15: All | K15: All | L15: Nearest 1%
A18: F107 | B18: Average age of full-time students | C18: 18 | D18: Student Life | E18: Average Age | F18: Degree-Seeking | G18: Undergraduates | H18: First-time, first-year | I18: All | J18: All | K18: All | L18: Whole Number or Round to Nearest Tenths
A19: F108 | B19: Average age of all students (full- and part-time) | C19: 18 | D19: Student Life | E19: Average Age | F19: Degree-Seeking | G19: Undergraduates | H19: First-time, first-year | I19: All | J19: All | K19: All | L19: Whole Number or Round to Nearest Tenths
A22: F109 | B22: Percent who are from out of state (exclude international/nonresidents from the numerator and denominator) | C22: 46 | D22: Student Life | E22: Percent Participating | F22: Degree-Seeking | G22: Undergraduates | H22: Undergraduates | I22: All | J22: All | K22: All | L22: Nearest 1%
A23: F110 | B23: Percent of men who join fraternities | C23: 9 | D23: Student Life | E23: Percent Participating | F23: Degree-Seeking | G23: Undergraduates | H23: Undergraduates | I23: All | J23: All | K23: All | L23: Nearest 1%
A24: F111 | B24: Percent of women who join sororities | C24: 8 | D24: Student Life | E24: Percent Participating | F24: Degree-Seeking | G24: Undergraduates | H24: Undergraduates | I24: All | J24: All | K24: All | L24: Nearest 1%
A25: F112 | B25: Percent who live in college-owned, -operated, or -affiliated housing | C25: 25 | D25: Student Life | E25: Percent Participating | F25: Degree-Seeking | G25: Undergraduates | H25: Undergraduates | I25: All | J25: All | K25: All | L25: Nearest 1%
... A31: F116 | B31: Average age of all students (full- and part-time) | C31: 20 | D31: Student Life | E31: Average Age | F31: Degree-Seeking | G31: Undergraduates | H31: Undergraduates | I31: All | J31: All | K31: All | L31: Whole Number or Round to Nearest Tenths
A37: F201 | B37: Campus Ministries | D37: Student Life | E37: Activities Offered | F37: All | G37: All | H37: All | I37: All | J37: All | K37: All | L37: x
A38: F202 | B38: Choral groups | C38: x | D38: Student Life | E38: Activities Offered | F38: All | G38: All | H38: All | I38: All | J38: All | K38: All | L38: x
A39: F203 | B39: Concert band | C39: x | D39: Student Life | E39: Activities Offered | F39: All | G39: All | H39: All | I39: All | J39: All | K39: All | L39: x
A40: F204 | B40: Dance | C40: x | D40: Student Life | E40: Activities Offered | F40: All | G40: All | H40: All | I40: All | J40: All | K40: All | L40: x
A41: F205 | B41: Drama/theater | C41: x | D41: Student Life | E41: Activities Offered | F41: All | G41: All | H41: All | I41: All | J41: All | K41: All | L41: x
A42: F206 | B42: International Student Organization | C42: x | D42: Student Life | E42: Activities Offered | F42: All | G42: All | H42: All | I42: All | J42: All | K42: All | L42: x
A43: F207 | B43: Jazz band | C43: x | D43: Student Life | E43: Activities Offered | F43: All | G43: All | H43: All | I43: All | J43: All | K43: All | L43: x
A44: F208 | B44: Literary magazine | C44: x | D44: Student Life | E44: Activities Offered | F44: All | G44: All | H44: All | I44: All | J44: All | K44: All | L44: x
A45: F209 | B45: Marching band | C45: x | D45: Student Life | E45: Activities Offered | F45: All | G45: All | H45: All | I45: All | J45: All | K45: All | L45: x
A46: F210 | B46: Model UN | D46: Student Life | E46: Activities Offered | F46: All | G46: All | H46: All | I46: All | J46: All | K46: All | L46: x
A47: F211 | B47: Music ensembles | C47: x | D47: Student Life | E47: Activities Offered | F47: All | G47: All | H47: All | I47: All | J47: All | K47: All | L47: x
A48: F212 | B48: Musical theater | C48: x | D48: Student Life | E48: Activities Offered | F48: All | G48: All | H48: All | I48: All | J48: All | K48: All | L48: x
A49: F213 | B49: Opera | C49: x | D49: Student Life | E49: Activities Offered | F49: All | G49: All | H49: All | I49: All | J49: All | K49: All | L49: x
A50: F214 | B50: Pep band | C50: x | D50: Student Life | E50: Activities Offered | F50: All | G50: All | H50: All | I50: All | J50: All | K50: All | L50: x
A51: F215 | B51: Radio station | C51: x | D51: Student Life | E51: Activities Offered | F51: All | G51: All | H51: All | I51: All | J51: All | K51: All | L51: x
A52: F216 | B52: Student government | C52: x | D52: Student Life | E52: Activities Offered | F52: All | G52: All | H52: All | I52: All | J52: All | K52: All | L52: x
A53: F217 | B53: Student newspaper | C53: x | D53: Student Life | E53: Activities Offered | F53: All | G53: All | H53: All | I53: All | J53: All | K53: All | L53: x
A54: F218 | B54: Student-run film society | C54: x | D54: Student Life | E54: Activities Offered | F54: All | G54: All | H54: All | I54: All | J54: All | K54: All | L54: x
A55: F219 | B55: Symphony orchestra | C55: x | D55: Student Life | E55: Activities Offered | F55: All | G55: All | H55: All | I55: All | J55: All | K55: All | L55: x
A56: F220 | B56: Television station | C56: x | D56: Student Life | E56: Activities Offered | F56: All | G56: All | H56: All | I56: All | J56: All | K56: All | L56: x
A57: F221 | B57: Yearbook | C57: x | D57: Student Life | E57: Activities Offered | F57: All | G57: All | H57: All | I57: All | J57: All | K57: All | L57: x
A64: F301 | B64: On Campus | C64: x | D64: Student Life | E64: ROTC | F64: Army | G64: All | H64: All | I64: All | J64: All | K64: All | L64: x
A65: F302 | B65: At Cooperating Institution | D65: Student Life | E65: ROTC | F65: Army | G65: All | H65: All | I65: All | J65: All | K65: All | L65: x
A67: F303 | B67: Name of Cooperating Institution | D67: Student Life | E67: ROTC | F67: Army | G67: All | H67: All | I67: All | J67: All | K67: All | L67: Text
A70: F304 | B70: Marine Option (for Naval ROTC) | C70: x | D70: Student Life | E70: ROTC | F70: Army | G70: All | H70: All | I70: All | J70: All | K70: All | L70: x
A71: F305 | B71: On Campus | C71: x | D71: Student Life | E71: ROTC | F71: Army | G71: All | H71: All | I71: All | J71: All | K71: All | L71: x
...

Sheet CDS-G
A1: Question Number | B1: Question | C1: Answer | D1: Section | E1: Sub-Section | F1: Category | G1: Student Group | H1: Cohort | I1: Residency | J1: Unit load | K1: Gender | L1: Value type
A7: G001 | B7: Please provide the URL of your institution’s net price calculator: | C7: https://app.meadowfi.com/wisconsin | D7: Annual Expenses | E7: Information | F7: All | G7: All | H7: All | I7: All | J7: All | K7: All | L7: URL
A9: G002 | B9: If your institution's 2025-2026 academic year costs of attendance are not available at this time please respond. | C9: x | D9: Annual Expenses | E9: Information | F9: All | G9: All | H9: All | I9: All | J9: All | K9: All | L9: x
A11: G003 | B11: Please provide an approximate date (i.e., month/day) when your institution's final 2025-2026 academic year costs of attendance will be available: | C11: 45870 | D11: Annual Expenses | E11: Information | F11: All | G11: All | H11: All | I11: All | J11: All | K11: All | L11: MM-DD
A26: G101 | B26: Tuition | D26: Annual Expenses | E26: Private Tuition | F26: Full-Time | G26: Undergraduate | H26: First-year | I26: All | J26: All | K26: All | L26: Nearest $1
A29: G102 | B29: Tuition | D29: Annual Expenses | E29: Private Tuition | F29: Full-Time | G29: Undergraduate | H29: Undergraduates | I29: All | J29: All | K29: All | L29: Nearest $1
A32: G103 | B32: Tuition: In-district | C32: 10506.48 | D32: Annual Expenses | E32: Public Tuition | F32: Full-Time | G32: Undergraduate | H32: First-year | I32: All | J32: All | K32: All | L32: Nearest $1
A33: G104 | B33: Tuition: In-state (out-of-district): | C33: 10506.48 | D33: Annual Expenses | E33: Public Tuition | F33: Full-Time | G33: Undergraduate | H33: First-year | I33: All | J33: All | K33: All | L33: Nearest $1
A34: G105 | B34: Tuition: Out-of-state: | C34: 42530.88 | D34: Annual Expenses | E34: Public Tuition | F34: Full-Time | G34: Undergraduate | H34: First-year | I34: All | J34: All | K34: All | L34: Nearest $1
A35: G106 | B35: Tuition: Non-resident | C35: 43530.96 | D35: Annual Expenses | E35: Public Tuition | F35: Full-Time | G35: Undergraduate | H35: First-year | I35: All | J35: All | K35: All | L35: Nearest $1
A38: G107 | B38: Tuition: In-district | C38: 10506.48 | D38: Annual Expenses | E38: Public Tuition | F38: Full-Time | G38: Undergraduate | H38: Undergraduates | I38: All | J38: All | K38: All | L38: Nearest $1
A39: G108 | B39: Tuition: In-state (out-of-district): | C39: 10506.48 | D39: Annual Expenses | E39: Public Tuition | F39: Full-Time | G39: Undergraduate | H39: Undergraduates | I39: All | J39: All | K39: All | L39: Nearest $1
A40: G109 | B40: Tuition: Out-of-state: | C40: 42530.88 | D40: Annual Expenses | E40: Public Tuition | F40: Full-Time | G40: Undergraduate | H40: Undergraduates | I40: All | J40: All | K40: All | L40: Nearest $1
A41: G110 | B41: Tuition: Non-resident | C41: 43530.96 | D41: Annual Expenses | E41: Public Tuition | F41: Full-Time | G41: Undergraduate | H41: Undergraduates | I41: All | J41: All | K41: All | L41: Nearest $1
A44: G111 | B44: Required Fees: | C44: 1659.98 | D44: Annual Expenses | E44: All Institutions Expenses | F44: Full-Time | G44: Undergraduate | H44: First-year | I44: All | J44: All | K44: All | L44: Nearest $1
A45: G112 | B45: Food and housing (on-campus): | C45: 14520 | D45: Annual Expenses | E45: All Institutions Expenses | F45: Full-Time | G45: Undergraduate | H45: First-year | I45: All | J45: All | K45: All | L45: Nearest $1
A46: G113 | B46: Housing Only (on-campus): | D46: Annual Expenses | E46: All Institutions Expenses | F46: Full-Time | G46: Undergraduate | H46: First-year | I46: All | J46: All | K46: All | L46: Nearest $1
A47: G114 | B47: Food Only (on-campus meal plan): | D47: Annual Expenses | E47: All Institutions Expenses | F47: Full-Time | G47: Undergraduate | H47: First-year | I47: All | J47: All | K47: All | L47: Nearest $1
A50: G115 | B50: Required Fees: | C50: 1660 | D50: Annual Expenses | E50: All Institutions Expenses | F50: Full-Time | G50: Undergraduate | H50: Undergraduates | I50: All | J50: All | K50: All | L50: Nearest $1
A51: G116 | B51: Food and housing (on-campus): | C51: 14520 | D51: Annual Expenses | E51: All Institutions Expenses | F51: Full-Time | G51: Undergraduate | H51: Undergraduates | I51: All | J51: All | K51: All | L51: Nearest $1
A52: G117 | B52: Housing Only (on-campus): | D52: Annual Expenses | E52: All Institutions Expenses | F52: Full-Time | G52: Undergraduate | H52: Undergraduates | I52: All | J52: All | K52: All | L52: Nearest $1
A53: G118 | B53: Food Only (on-campus meal plan): | D53: Annual Expenses | E53: All Institutions Expenses | F53: Full-Time | G53: Undergraduate | H53: Undergraduates | I53: All | J53: All | K53: All | L53: Nearest $1
A56: G119 | B56: Comprehensive tuition and food and housing fee (if your college cannot provide separate tuition and food and housing fees): | D56: Annual Expenses | E56: Comprehensive Expenses | F56: Full-Time | G56: Undergraduate | H56: All | I56: All | J56: All | K56: All | L56: Nearest $1
A59: G120 | B59: Other: | D59: Annual Expenses | E59: Comprehensive Expenses | F59: Full-Time | G59: Undergraduate | H59: All | I59: All | J59: All | K59: All | L59: Nearest $1
A62: G201 | B62: Minimum | C62: 12 | D62: Annual Expenses | E62: Credits per Term | F62: Full-Time | G62: Undergraduate | H62: All | I62: All | J62: All | K62: All | L62: Number
A63: G202 | B63: Maximum | C63: 18 | D63: Annual Expenses | E63: Credits per Term | F63: Full-Time | G63: Undergraduate | H63: All | I63: All | J63: All | K63: All | L63: Number
A66: G301 | B66: Do tuition and fees vary by year of study (e.g., sophomore, junior, senior)? | C66: N | D66: Annual Expenses | E66: Tuition Policies | F66: All | G66: All | H66: All | I66: All | J66: All | K66: All | L66: YN
A69: G401 | B69: Do tuition and fees vary by undergraduate instructional program? | C69: Y | D69: Annual Expenses | E69: Tuition Policies | F69: All | G69: All | H69: All | I69: All | J69: All | K69: All | L69: YN
A71: G402 | B71: If yes, what percentage of full-time undergraduates pay more than the tuition and fees reported in G1? | C71: 0.26 | D71: Annual Expenses | E71: Tuition Policies | F71: All | G71: All | H71: All | I71: All | J71: All | K71: All | L71: Nearest 1%
A78: G501 | B78: Books and supplies: | C78: 700 | D78: Annual Expenses | E78: Estimated Expenses | F78: Full-Time | G78: Undergraduate | H78: Residents | I78: All | J78: All | K78: All | L78: Nearest $1
A79: G502 | B79: Transportation: | C79: 600 | D79: Annual Expenses | E79: Estimated Expenses | F79: Full-Time | G79: Undergraduate | H79: Residents | I79: All | J79: All | K79: All | L79: Nearest $1
A80: G503 | B80: Other expenses: | C80: 2638 | D80: Annual Expenses | E80: Estimated Expenses | F80: Full-Time | G80: Undergraduate | H80: Residents | I80: All | J80: All | K80: All | L80: Nearest $1
A83: G504 | B83: Books and supplies: | C83: 700 | D83: Annual Expenses | E83: Estimated Expenses | F83: Full-Time | G83: Undergraduate | H83: Commuters (living at home) | I83: All | J83: All | K83: All | L83: Nearest $1
A84: G505 | B84: Food only: | C84: 4418 | D84: Annual Expenses | E84: Estimated Expenses | F84: Full-Time | G84: Undergraduate | H84: Commuters (living at home) | I84: All | J84: All | K84: All | L84: Nearest $1
A85: G506 | B85: Transportation | C85: 1300 | D85: Annual Expenses | E85: Estimated Expenses | F85: Full-Time | G85: Undergraduate | H85: Commuters (living at home) | I85: All | J85: All | K85: All | L85: Nearest $1
A86: G507 | B86: Other expenses: | C86: 2638 | D86: Annual Expenses | E86: Estimated Expenses | F86: Full-Time | G86: Undergraduate | H86: Commuters (living at home) | I86: All | J86: All | K86: All | L86: Nearest $1
A89: G508 | B89: Books and supplies: | C89: 700 | D89: Annual Expenses | E89: Estimated Expenses | F89: Full-Time | G89: Undergraduate | H89: Commuters (not living at home) | I89: All | J89: All | K89: All | L89: Nearest $1
A90: G509 | B90: Housing only: | D90: Annual Expenses | E90: Estimated Expenses | F90: Full-Time | G90: Undergraduate | H90: Commuters (not living at home) | I90: All | J90: All | K90: All | L90: Nearest $1
A91: G510 | B91: Food only: | D91: Annual Expenses | E91: Estimated Expenses | F91: Full-Time | G91: Undergraduate | H91: Commuters (not living at home) | I91: All | J91: All | K91: All | L91: Nearest $1
A92: G511 | B92: Food and housing total* | C92: 14520 | D92: Annual Expenses | E92: Estimated Expenses | F92: Full-Time | G92: Undergraduate | H92: Commuters (not living at home) | I92: All | J92: All | K92: All | L92: Nearest $1
...

Sheet CDS-H
A1: Question Number | B1: Question | C1: Answer | D1: Section | E1: Sub-Section | F1: Category | G1: Student Group | H1: Cohort | I1: Residency | J1: Unit load | K1: Gender | L1: Value type
B66: 2024-2025 | C66: x | D66: Financial Aid | E66: Reporting Year | F66: All | G66: All | H66: All | I66: All | J66: All | K66: All | L66: x
A67: H102 | B67: 2023-2024 Final | D67: Financial Aid | E67: Reporting Year | F67: All | G67: All | H67: All | I67: All | J67: All | K67: All | L67: x
A73: H103 | B73: Federal methodology (FM) | C73: x | D73: Financial Aid | E73: Methodology | F73: All | G73: All | H73: All | I73: All | J73: All | K73: All | L73: x
A74: H104 | B74: Institutional methodology (IM) | D74: Financial Aid | E74: Methodology | F74: All | G74: All | H74: All | I74: All | J74: All | K74: All | L74: x
A75: H105 | B75: Both FM and IM | D75: Financial Aid | E75: Methodology | F75: All | G75: All | H75: All | I75: All | J75: All | K75: All | L75: x
B80: Scholarships/Grants
A81: H106 | B81: Federal | C81: 44183661 | D81: Financial Aid | E81: Need-based Aid Awarded | F81: Degree-seeking | G81: Undergraduate | H81: Undergraduates | I81: All | J81: All | K81: All | L81: Nearest $1
A82: H107 | B82: State all states, not only the state in which your institution is located | C82: 15907355 | D82: Financial Aid | E82: Need-based Aid Awarded | F82: Degree-seeking | G82: Undergraduate | H82: Undergraduates | I82: All | J82: All | K82: All | L82: Nearest $1
